I'm sorry, but an uncaught exception occurred.

While running game code:
  File "game/scripts/game_content/leaders_den.rpy", line 63, in script
    if not quest.crocus.started:
  File "game/scripts/game_content/leaders_den.rpy", line 63, in <module>
    if not quest.crocus.started:
NameError: name 'quest' is not defined

-- Full Traceback ------------------------------------------------------------

Full traceback:
  File "game/scripts/game_content/leaders_den.rpy", line 63, in script
    if not quest.crocus.started:
  File "C:\Users\annie\Downloads\renpy-8.3.4-sdk\renpy\ast.py", line 1849, in execute
    if renpy.python.py_eval(condition):
  File "C:\Users\annie\Downloads\renpy-8.3.4-sdk\renpy\python.py", line 1209, in py_eval
    return py_eval_bytecode(code, globals, locals)
  File "C:\Users\annie\Downloads\renpy-8.3.4-sdk\renpy\python.py", line 1202, in py_eval_bytecode
    return eval(bytecode, globals, locals)
  File "game/scripts/game_content/leaders_den.rpy", line 63, in <module>
    if not quest.crocus.started:
NameError: name 'quest' is not defined

Windows-10-10.0.26100 AMD64
Ren'Py 8.3.4.24120703
 1.0
Wed Mar 12 20:10:17 2025
